from django.contrib.gis.geos import GEOSException
from django.test import TestCase

from .factories import LayerFactory


class LayerTestCase(TestCase):
    def setUp(self):
        self.layer = LayerFactory()

    def test_import_geojson(self):
        with_projection = """{"type": "FeatureCollection", "crs":
                             { "type": "name", "properties": { "name":
                             "urn:ogc:def:crs:OGC:1.3:CRS84" } },
                             "features": []}"""
        self.layer.from_geojson(with_projection, "01-01", "01-01")

        without_projection = """{"type": "FeatureCollection",
                                "features": []}"""
        self.layer.from_geojson(without_projection, "01-01", "01-01")

        with_bad_projection = """{"type": "FeatureCollection", "crs":
                                 { "type": "name", "properties": { "name":
                                 "BADPROJECTION" } }, "features": []}"""
        with self.assertRaises(GEOSException):
            self.layer.from_geojson(with_bad_projection, "01-01", "01-01")
